Workbook
Name clave: [1]Recursos!$AD$2
Name claveN: [1]Recursos!$AD$3
Name CoefUTCD: [1]UTC!$AA$3
Name flag01: INDIRECT([1]Dieciseisavos!$E$8)
Name flag02: INDIRECT([1]Dieciseisavos!$E$12)
Name flag03: INDIRECT([1]Dieciseisavos!$E$16)
Name flag04: INDIRECT([1]Dieciseisavos!$E$20)
Name flag05: INDIRECT([1]Dieciseisavos!$E$24)
Name flag06: INDIRECT([1]Dieciseisavos!$E$28)
Name flag07: INDIRECT([1]Dieciseisavos!$E$32)
Name flag08: INDIRECT([1]Dieciseisavos!$E$36)
Name flag09: INDIRECT([1]Dieciseisavos!$E$40)
Name flag10: INDIRECT([1]Dieciseisavos!$E$44)
Name flag11: INDIRECT([1]Dieciseisavos!$E$48)
Name flag12: INDIRECT([1]Dieciseisavos!$E$52)
Name flag13: INDIRECT([1]Dieciseisavos!$E$56)
Name flag14: INDIRECT([1]Dieciseisavos!$E$60)
Name flag15: INDIRECT([1]Dieciseisavos!$E$64)
Name flag16: INDIRECT([1]Dieciseisavos!$E$68)
Name flag17: INDIRECT([1]Dieciseisavos!$O$8)
Name flag18: INDIRECT([1]Dieciseisavos!$O$12)
Name flag19: INDIRECT([1]Dieciseisavos!$O$16)
Name flag20: INDIRECT([1]Dieciseisavos!$O$20)
Name flag21: INDIRECT([1]Dieciseisavos!$O$24)
Name flag22: INDIRECT([1]Dieciseisavos!$O$28)
Name flag23: INDIRECT([1]Dieciseisavos!$O$32)
Name flag24: INDIRECT([1]Dieciseisavos!$O$36)
Name flag25: INDIRECT([1]Dieciseisavos!$O$40)
Name flag26: INDIRECT([1]Dieciseisavos!$O$44)
Name flag27: INDIRECT([1]Dieciseisavos!$O$48)
Name flag28: INDIRECT([1]Dieciseisavos!$O$52)
Name flag29: INDIRECT([1]Dieciseisavos!$O$56)
Name flag30: INDIRECT([1]Dieciseisavos!$O$60)
Name flag31: INDIRECT([1]Dieciseisavos!$O$64)
Name flag32: INDIRECT([1]Dieciseisavos!$O$68)
Name flag33: INDIRECT([1]Octavos!$E$8)
Name flag34: INDIRECT([1]Octavos!$E$12)
Name flag35: INDIRECT([1]Octavos!$E$16)
Name flag36: INDIRECT([1]Octavos!$E$20)
Name flag37: INDIRECT([1]Octavos!$E$24)
Name flag38: INDIRECT([1]Octavos!$E$28)
Name flag39: INDIRECT([1]Octavos!$E$32)
Name flag40: INDIRECT([1]Octavos!$E$36)
Name flag41: INDIRECT([1]Octavos!$O$8)
Name flag42: INDIRECT([1]Octavos!$O$12)
Name flag43: INDIRECT([1]Octavos!$O$16)
Name flag44: INDIRECT([1]Octavos!$O$20)
Name flag45: INDIRECT([1]Octavos!$O$24)
Name flag46: INDIRECT([1]Octavos!$O$28)
Name flag47: INDIRECT([1]Octavos!$O$32)
Name flag48: INDIRECT([1]Octavos!$O$36)
Name flag49: INDIRECT([1]Cuartos!$E$8)
Name flag50: INDIRECT([1]Cuartos!$E$12)
Name flag51: INDIRECT([1]Cuartos!$E$16)
Name flag52: INDIRECT([1]Cuartos!$E$20)
Name flag53: INDIRECT([1]Cuartos!$O$8)
Name flag54: INDIRECT([1]Cuartos!$O$12)
Name flag55: INDIRECT([1]Cuartos!$O$16)
Name flag56: INDIRECT([1]Cuartos!$O$20)
Name flag57: INDIRECT([1]Semifinales!$E$8)

Sheet Polla - Grupos
A2: POLLA MUNDIALISTA 2026
A3: PRIMERA FASE - GRUPOS
A5: GRUPO A: MEXICO, SUDAFRICA, COREA DEL SUR, REPUBLICA CHECA
D7: 1 | E7: 2 | F7: 3 | G7: 4 | H7: 5 | I7: 6 | J7: 7 | K7: 8 | L7: 9 | M7: 10 | N7: 11 | O7: 12 | P7: 13 | Q7: 14 | R7: 15 | S7: 16 | T7: 17 | U7: 18 | V7: 19 | W7: 20 | X7: 21 | Y7: 22 | Z7: 23 | AA7: 24 | AB7: 25 | AC7: 26 | AD7: 27 | AE7: 28 | AF7: 29 | AG7: 30 | AH7: 31 | AI7: 32 | AJ7: 33 | AK7: 34 | AL7: 35 | AM7: 36 | AN7: 37 | AO7: 38 | AP7: 39 | AQ7: 40 | AR7: 41 | AS7: 42 | AT7: 43 | AU7: 44 | AV7: 45 | AW7: 46 | AX7: 47 | AY7: 48 | AZ7: 49 | BA7: 50 | BB7: 51 | BC7: 52 | BD7: 53 | BE7: 54 | BF7: 55 | BG7: 56 | BH7: 57 | BI7: 58 | BJ7: 59
B8: EQUIPO | C8: MARCADOR | D8: Julian Uribe | E8: Yulian Sanchez | F8: Francisco Moreno | G8: Mauricio Guerrero | H8: Gustavo Guerrero | I8: Gerardo Martinez | J8: Nora Perez | K8: Laura Rodriguez | L8: Jhoana Moreno | M8: Yoselin Salinas | N8: Luis Diaz | O8: Diela del Carmen | P8: Paola Agredo | Q8: Oscar Suarez | R8: Paulo Figueroa | S8: Jean Piere | T8: David Diaz | U8: Christian Giraldo | V8: Viviana Hurtado | W8: James Chavez Ocampo | X8: Luis Felipe Sanchez | Y8: Laura Ossa | Z8: Elizabeth Montealegre | AA8: Liliana Montealegre | AB8: Javier Andres Gomez | AC8: Diana Carolina Marin | AD8: Diego Fernando Saavedra | AE8: Oscar Mayor | AF8: Ingrid Toro | AG8: Ana Marcela Castro | AH8: Ricardo Gutierrez | AI8: Natalia Navarro | AJ8: Diana Perez | AK8: Sergio Diaz | AL8: William Oviedo | AM8: Armando Orjuela | AN8: Helen Muñoz | AO8: Julieth Cruz - Luiz Diaz | AP8: Jose Luis Montoya | AQ8: Julian Useche | AR8: Sebastian Posada | AS8: Juan Cifuentes | AT8: Rodrigo Dominguez | AU8: Carlos Calero | AV8: Lewhis Spirth Montaño | AW8: Sebastian Castro Luna | AX8: Francia Orozco | AY8: Fredy Rojas | AZ8: John Quiñonez | BA8: Yuli Guzman | BB8: Luis Alfredo Plaza | BC8: Naty Bermudez | BD8: Edgar Ivan Giraldo Duran | BE8: Caterine Filigrana | BF8: Adriana Belalcazar | BG8: Angelisa Hurtado | BH8: Isabela Muñoz | BI8: Francisco Moreno Alvarez | BJ8: Angelica Maria Panesso
A9: 1 | B9: MEXICO | D9: 3 | E9: 3 | F9: 2 | G9: 3 | H9: 2 | I9: 3 | J9: 2 | K9: 3 | L9: 2 | M9: 3 | N9: 2 | O9: 2 | P9: 3 | Q9: 2 | R9: 2 | S9: 2 | T9: 2 | U9: 2 | V9: 2 | W9: 1 | X9: 1 | Y9: 2 | Z9: 2 | AA9: 2 | AB9: 2 | AC9: 2 | AD9: 3 | AE9: 2 | AF9: 2 | AG9: 2 | AH9: 2 | AI9: 3 | AJ9: 3 | AK9: 2 | AL9: 2 | AM9: 1 | AN9: 2 | AO9: 3 | AP9: 2 | AQ9: 2 | AR9: 2 | AS9: 0 | AT9: 1 | AU9: 1 | AV9: 2 | AW9: 2 | AX9: 2 | AY9: 2 | AZ9: 2 | BA9: 1 | BB9: 1 | BC9: 2 | BD9: 2 | BE9: 2 | BF9: 2 | BG9: 2 | BH9: 2 | BI9: 2 | BJ9: 1
B10: SUDAFRICA | D10: 1 | E10: 2 | F10: 1 | G10: 0 | H10: 1 | I10: 1 | J10: 1 | K10: 0 | L10: 0 | M10: 1 | N10: 0 | O10: 0 | P10: 1 | Q10: 0 | R10: 0 | S10: 0 | T10: 0 | U10: 0 | V10: 1 | W10: 0 | X10: 1 | Y10: 0 | Z10: 1 | AA10: 1 | AB10: 0 | AC10: 1 | AD10: 1 | AE10: 1 | AF10: 0 | AG10: 0 | AH10: 0 | AI10: 2 | AJ10: 1 | AK10: 1 | AL10: 0 | AM10: 1 | AN10: 0 | AO10: 1 | AP10: 0 | AQ10: 1 | AR10: 1 | AS10: 2 | AT10: 0 | AU10: 0 | AV10: 1 | AW10: 0 | AX10: 1 | AY10: 0 | AZ10: 0 | BA10: 0 | BB10: 2 | BC10: 0 | BD10: 0 | BE10: 1 | BF10: 1 | BG10: 1 | BH10: 1 | BI10: 1 | BJ10: 0
B11: 46184 | C11: PUNTOS | D11: =IF($C9="",0,IF(AND(D9=$C9,D10=$C10),5,IF(OR(AND(D9-D10>0,$C9-$C10>0),AND(D10-D9>0,$C10-$C9>0),AND(D9-D10=0,$C9-$C10=0)),2,0)+IF(OR(D9=$C9,D10=$C10),1,0))) -> 0 | E11: =IF($C9="",0,IF(AND(E9=$C9,E10=$C10),5,IF(OR(AND(E9-E10>0,$C9-$C10>0),AND(E10-E9>0,$C10-$C9>0),AND(E9-E10=0,$C9-$C10=0)),2,0)+IF(OR(E9=$C9,E10=$C10),1,0))) -> 0 | F11: =IF($C9="",0,IF(AND(F9=$C9,F10=$C10),5,IF(OR(AND(F9-F10>0,$C9-$C10>0),AND(F10-F9>0,$C10-$C9>0),AND(F9-F10=0,$C9-$C10=0)),2,0)+IF(OR(F9=$C9,F10=$C10),1,0))) -> 0 | G11: =IF($C9="",0,IF(AND(G9=$C9,G10=$C10),5,IF(OR(AND(G9-G10>0,$C9-$C10>0),AND(G10-G9>0,$C10-$C9>0),AND(G9-G10=0,$C9-$C10=0)),2,0)+IF(OR(G9=$C9,G10=$C10),1,0))) -> 0 | H11: =IF($C9="",0,IF(AND(H9=$C9,H10=$C10),5,IF(OR(AND(H9-H10>0,$C9-$C10>0),AND(H10-H9>0,$C10-$C9>0),AND(H9-H10=0,$C9-$C10=0)),2,0)+IF(OR(H9=$C9,H10=$C10),1,0))) -> 0 | I11: =IF($C9="",0,IF(AND(I9=$C9,I10=$C10),5,IF(OR(AND(I9-I10>0,$C9-$C10>0),AND(I10-I9>0,$C10-$C9>0),AND(I9-I10=0,$C9-$C10=0)),2,0)+IF(OR(I9=$C9,I10=$C10),1,0))) -> 0 | J11: =IF($C9="",0,IF(AND(J9=$C9,J10=$C10),5,IF(OR(AND(J9-J10>0,$C9-$C10>0),AND(J10-J9>0,$C10-$C9>0),AND(J9-J10=0,$C9-$C10=0)),2,0)+IF(OR(J9=$C9,J10=$C10),1,0))) -> 0 | K11: =IF($C9="",0,IF(AND(K9=$C9,K10=$C10),5,IF(OR(AND(K9-K10>0,$C9-$C10>0),AND(K10-K9>0,$C10-$C9>0),AND(K9-K10=0,$C9-$C10=0)),2,0)+IF(OR(K9=$C9,K10=$C10),1,0))) -> 0 | ... BJ11: =IF($C9="",0,IF(AND(BJ9=$C9,BJ10=$C10),5,IF(OR(AND(BJ9-BJ10>0,$C9-$C10>0),AND(BJ10-BJ9>0,$C10-$C9>0),AND(BJ9-BJ10=0,$C9-$C10=0)),2,0)+IF(OR(BJ9=$C9,BJ10=$C10),1,0))) -> 0
B12: 0.58333333
A14: 2 | B14: COREA DEL SUR | D14: 1 | E14: 2 | F14: 3 | G14: 2 | H14: 1 | I14: 1 | J14: 1 | K14: 1 | L14: 1 | M14: 1 | N14: 1 | O14: 1 | P14: 1 | Q14: 3 | R14: 1 | S14: 2 | T14: 1 | U14: 1 | V14: 1 | W14: 1 | X14: 1 | Y14: 2 | Z14: 1 | AA14: 1 | AB14: 1 | AC14: 1 | AD14: 3 | AE14: 1 | AF14: 2 | AG14: 1 | AH14: 1 | AI14: 2 | AJ14: 2 | AK14: 1 | AL14: 1 | AM14: 1 | AN14: 1 | AO14: 1 | AP14: 1 | AQ14: 1 | AR14: 3 | AS14: 1 | AT14: 1 | AU14: 1 | AV14: 0 | AW14: 1 | AX14: 1 | AY14: 1 | AZ14: 2 | BA14: 2 | BB14: 1 | BC14: 1 | BD14: 2 | BE14: 1 | BF14: 2 | BG14: 1 | BH14: 1 | BI14: 0 | BJ14: 2
B15: REPUBLICA CHECA | D15: 1 | E15: 2 | F15: 2 | G15: 1 | H15: 1 | I15: 2 | J15: 1 | K15: 1 | L15: 1 | M15: 1 | N15: 1 | O15: 1 | P15: 0 | Q15: 1 | R15: 1 | S15: 1 | T15: 1 | U15: 1 | V15: 1 | W15: 1 | X15: 1 | Y15: 1 | Z15: 1 | AA15: 1 | AB15: 1 | AC15: 1 | AD15: 1 | AE15: 1 | AF15: 1 | AG15: 1 | AH15: 1 | AI15: 2 | AJ15: 0 | AK15: 1 | AL15: 0 | AM15: 2 | AN15: 1 | AO15: 2 | AP15: 1 | AQ15: 1 | AR15: 1 | AS15: 1 | AT15: 1 | AU15: 1 | AV15: 2 | AW15: 1 | AX15: 1 | AY15: 1 | AZ15: 1 | BA15: 1 | BB15: 0 | BC15: 1 | BD15: 1 | BE15: 0 | BF15: 1 | BG15: 1 | BH15: 0 | BI15: 2 | BJ15: 0
B16: 46184 | C16: PUNTOS | D16: =IF($C14="",0,IF(AND(D14=$C14,D15=$C15),5,IF(OR(AND(D14-D15>0,$C14-$C15>0),AND(D15-D14>0,$C15-$C14>0),AND(D14-D15=0,$C14-$C15=0)),2,0)+IF(OR(D14=$C14,D15=$C15),1,0))) -> 0 | E16: =IF($C14="",0,IF(AND(E14=$C14,E15=$C15),5,IF(OR(AND(E14-E15>0,$C14-$C15>0),AND(E15-E14>0,$C15-$C14>0),AND(E14-E15=0,$C14-$C15=0)),2,0)+IF(OR(E14=$C14,E15=$C15),1,0))) -> 0 | F16: =IF($C14="",0,IF(AND(F14=$C14,F15=$C15),5,IF(OR(AND(F14-F15>0,$C14-$C15>0),AND(F15-F14>0,$C15-$C14>0),AND(F14-F15=0,$C14-$C15=0)),2,0)+IF(OR(F14=$C14,F15=$C15),1,0))) -> 0 | G16: =IF($C14="",0,IF(AND(G14=$C14,G15=$C15),5,IF(OR(AND(G14-G15>0,$C14-$C15>0),AND(G15-G14>0,$C15-$C14>0),AND(G14-G15=0,$C14-$C15=0)),2,0)+IF(OR(G14=$C14,G15=$C15),1,0))) -> 0 | H16: =IF($C14="",0,IF(AND(H14=$C14,H15=$C15),5,IF(OR(AND(H14-H15>0,$C14-$C15>0),AND(H15-H14>0,$C15-$C14>0),AND(H14-H15=0,$C14-$C15=0)),2,0)+IF(OR(H14=$C14,H15=$C15),1,0))) -> 0 | I16: =IF($C14="",0,IF(AND(I14=$C14,I15=$C15),5,IF(OR(AND(I14-I15>0,$C14-$C15>0),AND(I15-I14>0,$C15-$C14>0),AND(I14-I15=0,$C14-$C15=0)),2,0)+IF(OR(I14=$C14,I15=$C15),1,0))) -> 0 | J16: =IF($C14="",0,IF(AND(J14=$C14,J15=$C15),5,IF(OR(AND(J14-J15>0,$C14-$C15>0),AND(J15-J14>0,$C15-$C14>0),AND(J14-J15=0,$C14-$C15=0)),2,0)+IF(OR(J14=$C14,J15=$C15),1,0))) -> 0 | K16: =IF($C14="",0,IF(AND(K14=$C14,K15=$C15),5,IF(OR(AND(K14-K15>0,$C14-$C15>0),AND(K15-K14>0,$C15-$C14>0),AND(K14-K15=0,$C14-$C15=0)),2,0)+IF(OR(K14=$C14,K15=$C15),1,0))) -> 0 | ... BJ16: =IF($C14="",0,IF(AND(BJ14=$C14,BJ15=$C15),5,IF(OR(AND(BJ14-BJ15>0,$C14-$C15>0),AND(BJ15-BJ14>0,$C15-$C14>0),AND(BJ14-BJ15=0,$C14-$C15=0)),2,0)+IF(OR(BJ14=$C14,BJ15=$C15),1,0))) -> 0
B17: 0.79166667
A19: 25 | B19: REPUBLICA CHECA | D19: 2 | E19: 1 | F19: 0 | G19: 2 | H19: 1 | I19: 3 | J19: 1 | K19: 2 | L19: 2 | M19: 2 | N19: 1 | O19: 2 | P19: 1 | Q19: 1 | R19: 1 | S19: 1 | T19: 1 | U19: 1 | V19: 2 | W19: 4 | X19: 1 | Y19: 2 | Z19: 1 | AA19: 2 | AB19: 2 | AC19: 1 | AD19: 0 | AE19: 1 | AF19: 1 | AG19: 2 | AH19: 1 | AI19: 1 | AJ19: 0 | AK19: 1 | AL19: 0 | AM19: 2 | AN19: 2 | AO19: 2 | AP19: 1 | AQ19: 1 | AR19: 2 | AS19: 0 | AT19: 1 | AU19: 2 | AV19: 1 | AW19: 2 | AX19: 2 | AY19: 2 | AZ19: 2 | BA19: 1 | BB19: 0 | BC19: 2 | BD19: 2 | BE19: 2 | BF19: 1 | BG19: 2 | BH19: 1 | BI19: 1 | BJ19: 1
B20: SUDAFRICA | D20: 0 | E20: 1 | F20: 0 | G20: 0 | H20: 1 | I20: 2 | J20: 0 | K20: 0 | L20: 0 | M20: 0 | N20: 0 | O20: 1 | P20: 1 | Q20: 1 | R20: 0 | S20: 0 | T20: 0 | U20: 0 | V20: 1 | W20: 1 | X20: 0 | Y20: 0 | Z20: 2 | AA20: 0 | AB20: 0 | AC20: 1 | AD20: 2 | AE20: 0 | AF20: 1 | AG20: 1 | AH20: 0 | AI20: 1 | AJ20: 2 | AK20: 0 | AL20: 1 | AM20: 2 | AN20: 0 | AO20: 0 | AP20: 0 | AQ20: 0 | AR20: 2 | AS20: 1 | AT20: 0 | AU20: 1 | AV20: 1 | AW20: 1 | AX20: 0 | AY20: 1 | AZ20: 2 | BA20: 1 | BB20: 3 | BC20: 0 | BD20: 1 | BE20: 1 | BF20: 0 | BG20: 1 | BH20: 1 | BI20: 1 | BJ20: 1
B21: 46191 | C21: PUNTOS | D21: =IF($C19="",0,IF(AND(D19=$C19,D20=$C20),5,IF(OR(AND(D19-D20>0,$C19-$C20>0),AND(D20-D19>0,$C20-$C19>0),AND(D19-D20=0,$C19-$C20=0)),2,0)+IF(OR(D19=$C19,D20=$C20),1,0))) -> 0 | E21: =IF($C19="",0,IF(AND(E19=$C19,E20=$C20),5,IF(OR(AND(E19-E20>0,$C19-$C20>0),AND(E20-E19>0,$C20-$C19>0),AND(E19-E20=0,$C19-$C20=0)),2,0)+IF(OR(E19=$C19,E20=$C20),1,0))) -> 0 | F21: =IF($C19="",0,IF(AND(F19=$C19,F20=$C20),5,IF(OR(AND(F19-F20>0,$C19-$C20>0),AND(F20-F19>0,$C20-$C19>0),AND(F19-F20=0,$C19-$C20=0)),2,0)+IF(OR(F19=$C19,F20=$C20),1,0))) -> 0 | G21: =IF($C19="",0,IF(AND(G19=$C19,G20=$C20),5,IF(OR(AND(G19-G20>0,$C19-$C20>0),AND(G20-G19>0,$C20-$C19>0),AND(G19-G20=0,$C19-$C20=0)),2,0)+IF(OR(G19=$C19,G20=$C20),1,0))) -> 0 | H21: =IF($C19="",0,IF(AND(H19=$C19,H20=$C20),5,IF(OR(AND(H19-H20>0,$C19-$C20>0),AND(H20-H19>0,$C20-$C19>0),AND(H19-H20=0,$C19-$C20=0)),2,0)+IF(OR(H19=$C19,H20=$C20),1,0))) -> 0 | I21: =IF($C19="",0,IF(AND(I19=$C19,I20=$C20),5,IF(OR(AND(I19-I20>0,$C19-$C20>0),AND(I20-I19>0,$C20-$C19>0),AND(I19-I20=0,$C19-$C20=0)),2,0)+IF(OR(I19=$C19,I20=$C20),1,0))) -> 0 | J21: =IF($C19="",0,IF(AND(J19=$C19,J20=$C20),5,IF(OR(AND(J19-J20>0,$C19-$C20>0),AND(J20-J19>0,$C20-$C19>0),AND(J19-J20=0,$C19-$C20=0)),2,0)+IF(OR(J19=$C19,J20=$C20),1,0))) -> 0 | K21: =IF($C19="",0,IF(AND(K19=$C19,K20=$C20),5,IF(OR(AND(K19-K20>0,$C19-$C20>0),AND(K20-K19>0,$C20-$C19>0),AND(K19-K20=0,$C19-$C20=0)),2,0)+IF(OR(K19=$C19,K20=$C20),1,0))) -> 0 | ... BJ21: =IF($C19="",0,IF(AND(BJ19=$C19,BJ20=$C20),5,IF(OR(AND(BJ19-BJ20>0,$C19-$C20>0),AND(BJ20-BJ19>0,$C20-$C19>0),AND(BJ19-BJ20=0,$C19-$C20=0)),2,0)+IF(OR(BJ19=$C19,BJ20=$C20),1,0))) -> 0
B22: 0.45833333
A24: 28 | B24: MEXICO | D24: 2 | E24: 1 | F24: 2 | G24: 2 | H24: 2 | I24: 4 | J24: 2 | K24: 1 | L24: 1 | M24: 2 | N24: 2 | O24: 2 | P24: 1 | Q24: 2 | R24: 2 | S24: 2 | T24: 2 | U24: 2 | V24: 2 | W24: 0 | X24: 0 | Y24: 2 | Z24: 2 | AA24: 0 | AB24: 2 | AC24: 1 | AD24: 2 | AE24: 1 | AF24: 2 | AG24: 2 | AH24: 2 | AI24: 2 | AJ24: 2 | AK24: 1 | AL24: 0 | AM24: 1 | AN24: 2 | AO24: 2 | AP24: 1 | AQ24: 2 | AR24: 0 | AS24: 1 | AT24: 1 | AU24: 2 | AV24: 3 | AW24: 3 | AX24: 2 | AY24: 1 | AZ24: 1 | BA24: 1 | BB24: 2 | BC24: 2 | BD24: 2 | BE24: 1 | BF24: 2 | BG24: 1 | BH24: 2 | BI24: 1 | BJ24: 1
B25: COREA DEL SUR | D25: 1 | E25: 1 | F25: 1 | G25: 1 | H25: 0 | I25: 1 | J25: 0 | K25: 1 | L25: 1 | M25: 2 | N25: 1 | O25: 1 | P25: 0 | Q25: 1 | R25: 1 | S25: 1 | T25: 1 | U25: 1 | V25: 1 | W25: 1 | X25: 2 | Y25: 1 | Z25: 0 | AA25: 0 | AB25: 1 | AC25: 0 | AD25: 2 | AE25: 1 | AF25: 1 | AG25: 1 | AH25: 1 | AI25: 1 | AJ25: 2 | AK25: 1 | AL25: 2 | AM25: 0 | AN25: 1 | AO25: 1 | AP25: 1 | AQ25: 0 | AR25: 1 | AS25: 2 | AT25: 2 | AU25: 1 | AV25: 1 | AW25: 0 | AX25: 0 | AY25: 1 | AZ25: 1 | BA25: 1 | BB25: 0 | BC25: 1 | BD25: 2 | BE25: 0 | BF25: 1 | BG25: 0 | BH25: 2 | BI25: 1 | BJ25: 2
B26: 46191 | C26: PUNTOS | D26: =IF($C24="",0,IF(AND(D24=$C24,D25=$C25),5,IF(OR(AND(D24-D25>0,$C24-$C25>0),AND(D25-D24>0,$C25-$C24>0),AND(D24-D25=0,$C24-$C25=0)),2,0)+IF(OR(D24=$C24,D25=$C25),1,0))) -> 0 | E26: =IF($C24="",0,IF(AND(E24=$C24,E25=$C25),5,IF(OR(AND(E24-E25>0,$C24-$C25>0),AND(E25-E24>0,$C25-$C24>0),AND(E24-E25=0,$C24-$C25=0)),2,0)+IF(OR(E24=$C24,E25=$C25),1,0))) -> 0 | F26: =IF($C24="",0,IF(AND(F24=$C24,F25=$C25),5,IF(OR(AND(F24-F25>0,$C24-$C25>0),AND(F25-F24>0,$C25-$C24>0),AND(F24-F25=0,$C24-$C25=0)),2,0)+IF(OR(F24=$C24,F25=$C25),1,0))) -> 0 | G26: =IF($C24="",0,IF(AND(G24=$C24,G25=$C25),5,IF(OR(AND(G24-G25>0,$C24-$C25>0),AND(G25-G24>0,$C25-$C24>0),AND(G24-G25=0,$C24-$C25=0)),2,0)+IF(OR(G24=$C24,G25=$C25),1,0))) -> 0 | H26: =IF($C24="",0,IF(AND(H24=$C24,H25=$C25),5,IF(OR(AND(H24-H25>0,$C24-$C25>0),AND(H25-H24>0,$C25-$C24>0),AND(H24-H25=0,$C24-$C25=0)),2,0)+IF(OR(H24=$C24,H25=$C25),1,0))) -> 0 | I26: =IF($C24="",0,IF(AND(I24=$C24,I25=$C25),5,IF(OR(AND(I24-I25>0,$C24-$C25>0),AND(I25-I24>0,$C25-$C24>0),AND(I24-I25=0,$C24-$C25=0)),2,0)+IF(OR(I24=$C24,I25=$C25),1,0))) -> 0 | J26: =IF($C24="",0,IF(AND(J24=$C24,J25=$C25),5,IF(OR(AND(J24-J25>0,$C24-$C25>0),AND(J25-J24>0,$C25-$C24>0),AND(J24-J25=0,$C24-$C25=0)),2,0)+IF(OR(J24=$C24,J25=$C25),1,0))) -> 0 | K26: =IF($C24="",0,IF(AND(K24=$C24,K25=$C25),5,IF(OR(AND(K24-K25>0,$C24-$C25>0),AND(K25-K24>0,$C25-$C24>0),AND(K24-K25=0,$C24-$C25=0)),2,0)+IF(OR(K24=$C24,K25=$C25),1,0))) -> 0 | ... BJ26: =IF($C24="",0,IF(AND(BJ24=$C24,BJ25=$C25),5,IF(OR(AND(BJ24-BJ25>0,$C24-$C25>0),AND(BJ25-BJ24>0,$C25-$C24>0),AND(BJ24-BJ25=0,$C24-$C25=0)),2,0)+IF(OR(BJ24=$C24,BJ25=$C25),1,0))) -> 0
B27: 0.75
A29: 53 | B29: REPUBLICA CHECA | D29: 1 | E29: 0 | F29: 2 | G29: 0 | H29: 1 | I29: 2 | J29: 1 | K29: 1 | L29: 1 | M29: 1 | N29: 1 | O29: 1 | P29: 1 | Q29: 0 | R29: 1 | S29: 1 | T29: 1 | U29: 1 | V29: 1 | W29: 2 | X29: 1 | Y29: 0 | Z29: 0 | AA29: 2 | AB29: 0 | AC29: 1 | AD29: 1 | AE29: 0 | AF29: 1 | AG29: 1 | AH29: 0 | AI29: 2 | AJ29: 0 | AK29: 1 | AL29: 2 | AM29: 2 | AN29: 1 | AO29: 1 | AP29: 1 | AQ29: 1 | AR29: 0 | AS29: 1 | AT29: 0 | AU29: 1 | AV29: 0 | AW29: 1 | AX29: 1 | AY29: 1 | AZ29: 0 | BA29: 1 | BB29: 0 | BC29: 1 | BD29: 0 | BE29: 0 | BF29: 0 | BG29: 1 | BH29: 0 | BI29: 2 | BJ29: 1
B30: MEXICO | D30: 1 | E30: 1 | F30: 1 | G30: 1 | H30: 2 | I30: 2 | J30: 2 | K30: 2 | L30: 2 | M30: 1 | N30: 1 | O30: 1 | P30: 2 | Q30: 1 | R30: 1 | S30: 1 | T30: 1 | U30: 1 | V30: 2 | W30: 2 | X30: 1 | Y30: 1 | Z30: 2 | AA30: 2 | AB30: 1 | AC30: 2 | AD30: 1 | AE30: 1 | AF30: 2 | AG30: 2 | AH30: 1 | AI30: 2 | AJ30: 2 | AK30: 2 | AL30: 2 | AM30: 2 | AN30: 1 | AO30: 1 | AP30: 2 | AQ30: 1 | AR30: 2 | AS30: 1 | AT30: 1 | AU30: 1 | AV30: 1 | AW30: 2 | AX30: 2 | AY30: 2 | AZ30: 1 | BA30: 2 | BB30: 1 | BC30: 1 | BD30: 1 | BE30: 1 | BF30: 1 | BG30: 2 | BH30: 1 | BI30: 2 | BJ30: 1
B31: 46197 | C31: PUNTOS | D31: =IF($C29="",0,IF(AND(D29=$C29,D30=$C30),5,IF(OR(AND(D29-D30>0,$C29-$C30>0),AND(D30-D29>0,$C30-$C29>0),AND(D29-D30=0,$C29-$C30=0)),2,0)+IF(OR(D29=$C29,D30=$C30),1,0))) -> 0 | E31: =IF($C29="",0,IF(AND(E29=$C29,E30=$C30),5,IF(OR(AND(E29-E30>0,$C29-$C30>0),AND(E30-E29>0,$C30-$C29>0),AND(E29-E30=0,$C29-$C30=0)),2,0)+IF(OR(E29=$C29,E30=$C30),1,0))) -> 0 | F31: =IF($C29="",0,IF(AND(F29=$C29,F30=$C30),5,IF(OR(AND(F29-F30>0,$C29-$C30>0),AND(F30-F29>0,$C30-$C29>0),AND(F29-F30=0,$C29-$C30=0)),2,0)+IF(OR(F29=$C29,F30=$C30),1,0))) -> 0 | G31: =IF($C29="",0,IF(AND(G29=$C29,G30=$C30),5,IF(OR(AND(G29-G30>0,$C29-$C30>0),AND(G30-G29>0,$C30-$C29>0),AND(G29-G30=0,$C29-$C30=0)),2,0)+IF(OR(G29=$C29,G30=$C30),1,0))) -> 0 | H31: =IF($C29="",0,IF(AND(H29=$C29,H30=$C30),5,IF(OR(AND(H29-H30>0,$C29-$C30>0),AND(H30-H29>0,$C30-$C29>0),AND(H29-H30=0,$C29-$C30=0)),2,0)+IF(OR(H29=$C29,H30=$C30),1,0))) -> 0 | I31: =IF($C29="",0,IF(AND(I29=$C29,I30=$C30),5,IF(OR(AND(I29-I30>0,$C29-$C30>0),AND(I30-I29>0,$C30-$C29>0),AND(I29-I30=0,$C29-$C30=0)),2,0)+IF(OR(I29=$C29,I30=$C30),1,0))) -> 0 | J31: =IF($C29="",0,IF(AND(J29=$C29,J30=$C30),5,IF(OR(AND(J29-J30>0,$C29-$C30>0),AND(J30-J29>0,$C30-$C29>0),AND(J29-J30=0,$C29-$C30=0)),2,0)+IF(OR(J29=$C29,J30=$C30),1,0))) -> 0 | K31: =IF($C29="",0,IF(AND(K29=$C29,K30=$C30),5,IF(OR(AND(K29-K30>0,$C29-$C30>0),AND(K30-K29>0,$C30-$C29>0),AND(K29-K30=0,$C29-$C30=0)),2,0)+IF(OR(K29=$C29,K30=$C30),1,0))) -> 0 | ... BJ31: =IF($C29="",0,IF(AND(BJ29=$C29,BJ30=$C30),5,IF(OR(AND(BJ29-BJ30>0,$C29-$C30>0),AND(BJ30-BJ29>0,$C30-$C29>0),AND(BJ29-BJ30=0,$C29-$C30=0)),2,0)+IF(OR(BJ29=$C29,BJ30=$C30),1,0))) -> 0
B32: 0.83333333
A34: 54 | B34: SUDAFRICA | D34: 0 | E34: 1 | F34: 2 | G34: 0 | H34: 1 | I34: 2 | J34: 0 | K34: 2 | L34: 0 | M34: 0 | N34: 1 | O34: 1 | P34: 0 | Q34: 2 | R34: 0 | S34: 0 | T34: 1 | U34: 0 | V34: 1 | W34: 0 | X34: 0 | Y34: 0 | Z34: 1 | AA34: 2 | AB34: 0 | AC34: 0 | AD34: 2 | AE34: 1 | AF34: 0 | AG34: 1 | AH34: 1 | AI34: 3 | AJ34: 2 | AK34: 0 | AL34: 2 | AM34: 2 | AN34: 1 | AO34: 1 | AP34: 1 | AQ34: 0 | AR34: 1 | AS34: 1 | AT34: 1 | AU34: 1 | AV34: 2 | AW34: 1 | AX34: 0 | AY34: 1 | AZ34: 0 | BA34: 0 | BB34: 2 | BC34: 0 | BD34: 0 | BE34: 1 | BF34: 0 | BG34: 1 | BH34: 0 | BI34: 0 | BJ34: 0
B35: COREA DEL SUR | D35: 1 | E35: 2 | F35: 2 | G35: 2 | H35: 2 | I35: 0 | J35: 1 | K35: 1 | L35: 2 | M35: 2 | N35: 2 | O35: 2 | P35: 1 | Q35: 2 | R35: 2 | S35: 2 | T35: 1 | U35: 3 | V35: 1 | W35: 2 | X35: 0 | Y35: 2 | Z35: 2 | AA35: 0 | AB35: 2 | AC35: 2 | AD35: 2 | AE35: 2 | AF35: 1 | AG35: 2 | AH35: 2 | AI35: 3 | AJ35: 1 | AK35: 2 | AL35: 3 | AM35: 0 | AN35: 2 | AO35: 2 | AP35: 0 | AQ35: 1 | AR35: 3 | AS35: 0 | AT35: 2 | AU35: 2 | AV35: 1 | AW35: 1 | AX35: 1 | AY35: 2 | AZ35: 2 | BA35: 3 | BB35: 1 | BC35: 2 | BD35: 2 | BE35: 1 | BF35: 2 | BG35: 0 | BH35: 2 | BI35: 0 | BJ35: 2
B36: 46197 | C36: PUNTOS | D36: =IF($C34="",0,IF(AND(D34=$C34,D35=$C35),5,IF(OR(AND(D34-D35>0,$C34-$C35>0),AND(D35-D34>0,$C35-$C34>0),AND(D34-D35=0,$C34-$C35=0)),2,0)+IF(OR(D34=$C34,D35=$C35),1,0))) -> 0 | E36: =IF($C34="",0,IF(AND(E34=$C34,E35=$C35),5,IF(OR(AND(E34-E35>0,$C34-$C35>0),AND(E35-E34>0,$C35-$C34>0),AND(E34-E35=0,$C34-$C35=0)),2,0)+IF(OR(E34=$C34,E35=$C35),1,0))) -> 0 | F36: =IF($C34="",0,IF(AND(F34=$C34,F35=$C35),5,IF(OR(AND(F34-F35>0,$C34-$C35>0),AND(F35-F34>0,$C35-$C34>0),AND(F34-F35=0,$C34-$C35=0)),2,0)+IF(OR(F34=$C34,F35=$C35),1,0))) -> 0 | G36: =IF($C34="",0,IF(AND(G34=$C34,G35=$C35),5,IF(OR(AND(G34-G35>0,$C34-$C35>0),AND(G35-G34>0,$C35-$C34>0),AND(G34-G35=0,$C34-$C35=0)),2,0)+IF(OR(G34=$C34,G35=$C35),1,0))) -> 0 | H36: =IF($C34="",0,IF(AND(H34=$C34,H35=$C35),5,IF(OR(AND(H34-H35>0,$C34-$C35>0),AND(H35-H34>0,$C35-$C34>0),AND(H34-H35=0,$C34-$C35=0)),2,0)+IF(OR(H34=$C34,H35=$C35),1,0))) -> 0 | I36: =IF($C34="",0,IF(AND(I34=$C34,I35=$C35),5,IF(OR(AND(I34-I35>0,$C34-$C35>0),AND(I35-I34>0,$C35-$C34>0),AND(I34-I35=0,$C34-$C35=0)),2,0)+IF(OR(I34=$C34,I35=$C35),1,0))) -> 0 | J36: =IF($C34="",0,IF(AND(J34=$C34,J35=$C35),5,IF(OR(AND(J34-J35>0,$C34-$C35>0),AND(J35-J34>0,$C35-$C34>0),AND(J34-J35=0,$C34-$C35=0)),2,0)+IF(OR(J34=$C34,J35=$C35),1,0))) -> 0 | K36: =IF($C34="",0,IF(AND(K34=$C34,K35=$C35),5,IF(OR(AND(K34-K35>0,$C34-$C35>0),AND(K35-K34>0,$C35-$C34>0),AND(K34-K35=0,$C34-$C35=0)),2,0)+IF(OR(K34=$C34,K35=$C35),1,0))) -> 0 | ... BJ36: =IF($C34="",0,IF(AND(BJ34=$C34,BJ35=$C35),5,IF(OR(AND(BJ34-BJ35>0,$C34-$C35>0),AND(BJ35-BJ34>0,$C35-$C34>0),AND(BJ34-BJ35=0,$C34-$C35=0)),2,0)+IF(OR(BJ34=$C34,BJ35=$C35),1,0))) -> 0
B37: 0.83333333
A41: GRUPO B: CANADA, BOSNIA, CATAR, SUIZA
D43: 1 | E43: 2 | F43: 3 | G43: 4 | H43: 5 | I43: 6 | J43: 7 | K43: 8 | L43: 9 | M43: 10 | N43: 11 | O43: 13 | P43: 14 | Q43: 15 | R43: 16 | S43: 17 | T43: 18 | U43: 19 | V43: 20 | W43: 21 | X43: 22 | Y43: 24 | Z43: 25 | AA43: 26 | AB43: 27 | AC43: 29 | AD43: 30 | AE43: 32 | AF43: 33 | AG43: 34 | AH43: 35 | AI43: 36 | AJ43: 37 | AK43: 38 | AL43: 39 | AM43: 40 | AN43: 41 | AO43: 42 | AP43: 44 | AQ43: 67 | AR43: 48 | AS43: 49 | AT43: 51 | AU43: 52 | AV43: 53 | AW43: 54 | AX43: 55 | AY43: 56 | AZ43: 57 | BA43: 58 | BB43: 59 | BC43: 60 | BD43: 61 | BE43: 62 | BF43: 63 | BG43: 64 | BH43: 65 | BI43: 66 | BJ43: 67
B44: EQUIPO | C44: MARCADOR | D44: =$D$8 -> Julian Uribe | E44: =$E$8 -> Yulian Sanchez | F44: =$F$8 -> Francisco Moreno | G44: =$G$8 -> Mauricio Guerrero | H44: =$H$8 -> Gustavo Guerrero | I44: =$I$8 -> Gerardo Martinez | J44: =J8 -> Nora Perez | K44: =K8 -> Laura Rodriguez | L44: =L8 -> Jhoana Moreno | M44: =M8 -> Yoselin Salinas | N44: =N8 -> Luis Diaz | O44: =O8 -> Diela del Carmen | P44: =P8 -> Paola Agredo | Q44: =Q8 -> Oscar Suarez | ... BJ44: =BJ8 -> Angelica Maria Panesso
A45: 3 | B45: CANADA | D45: 1 | E45: 3 | F45: 1 | G45: 3 | H45: 2 | I45: 1 | J45: 2 | K45: 2 | L45: 2 | M45: 2 | N45: 2 | O45: 2 | P45: 2 | Q45: 1 | R45: 1 | S45: 2 | T45: 2 | U45: 0 | V45: 1 | W45: 2 | X45: 3 | Y45: 1 | Z45: 2 | AA45: 2 | AB45: 2 | AC45: 1 | AD45: 2 | AE45: 2 | AF45: 2 | AG45: 2 | AH45: 2 | AI45: 1 | AJ45: 2 | AK45: 0 | AL45: 0 | AM45: 3 | AN45: 1 | AO45: 2 | AP45: 1 | AQ45: 2 | AR45: 2 | AS45: 0 | AT45: 0 | AU45: 2 | AV45: 1 | AW45: 2 | AX45: 3 | AY45: 2 | AZ45: 2 | BA45: 1 | BB45: 2 | BC45: 1 | BD45: 2 | BE45: 1 | BF45: 1 | BG45: 1 | BH45: 1 | BI45: 3 | BJ45: 1
B46: BOSNIA | D46: 2 | E46: 1 | F46: 1 | G46: 0 | H46: 1 | I46: 2 | J46: 0 | K46: 0 | L46: 1 | M46: 1 | N46: 1 | O46: 1 | P46: 1 | Q46: 0 | R46: 1 | S46: 1 | T46: 0 | U46: 2 | V46: 1 | W46: 1 | X46: 0 | Y46: 1 | Z46: 1 | AA46: 1 | AB46: 1 | AC46: 1 | AD46: 0 | AE46: 1 | AF46: 0 | AG46: 1 | AH46: 1 | AI46: 1 | AJ46: 0 | AK46: 0 | AL46: 1 | AM46: 1 | AN46: 2 | AO46: 0 | AP46: 0 | AQ46: 0 | AR46: 1 | AS46: 1 | AT46: 2 | AU46: 0 | AV46: 0 | AW46: 1 | AX46: 1 | AY46: 1 | AZ46: 0 | BA46: 2 | BB46: 0 | BC46: 0 | BD46: 0 | BE46: 1 | BF46: 1 | BG46: 2 | BH46: 0 | BI46: 0 | BJ46: 0
B47: 46185 | C47: PUNTOS | D47: =IF($C45="",0,IF(AND(D45=$C45,D46=$C46),5,IF(OR(AND(D45-D46>0,$C45-$C46>0),AND(D46-D45>0,$C46-$C45>0),AND(D45-D46=0,$C45-$C46=0)),2,0)+IF(OR(D45=$C45,D46=$C46),1,0))) -> 0 | E47: =IF($C45="",0,IF(AND(E45=$C45,E46=$C46),5,IF(OR(AND(E45-E46>0,$C45-$C46>0),AND(E46-E45>0,$C46-$C45>0),AND(E45-E46=0,$C45-$C46=0)),2,0)+IF(OR(E45=$C45,E46=$C46),1,0))) -> 0 | F47: =IF($C45="",0,IF(AND(F45=$C45,F46=$C46),5,IF(OR(AND(F45-F46>0,$C45-$C46>0),AND(F46-F45>0,$C46-$C45>0),AND(F45-F46=0,$C45-$C46=0)),2,0)+IF(OR(F45=$C45,F46=$C46),1,0))) -> 0 | G47: =IF($C45="",0,IF(AND(G45=$C45,G46=$C46),5,IF(OR(AND(G45-G46>0,$C45-$C46>0),AND(G46-G45>0,$C46-$C45>0),AND(G45-G46=0,$C45-$C46=0)),2,0)+IF(OR(G45=$C45,G46=$C46),1,0))) -> 0 | H47: =IF($C45="",0,IF(AND(H45=$C45,H46=$C46),5,IF(OR(AND(H45-H46>0,$C45-$C46>0),AND(H46-H45>0,$C46-$C45>0),AND(H45-H46=0,$C45-$C46=0)),2,0)+IF(OR(H45=$C45,H46=$C46),1,0))) -> 0 | I47: =IF($C45="",0,IF(AND(I45=$C45,I46=$C46),5,IF(OR(AND(I45-I46>0,$C45-$C46>0),AND(I46-I45>0,$C46-$C45>0),AND(I45-I46=0,$C45-$C46=0)),2,0)+IF(OR(I45=$C45,I46=$C46),1,0))) -> 0 | J47: =IF($C45="",0,IF(AND(J45=$C45,J46=$C46),5,IF(OR(AND(J45-J46>0,$C45-$C46>0),AND(J46-J45>0,$C46-$C45>0),AND(J45-J46=0,$C45-$C46=0)),2,0)+IF(OR(J45=$C45,J46=$C46),1,0))) -> 0 | K47: =IF($C45="",0,IF(AND(K45=$C45,K46=$C46),5,IF(OR(AND(K45-K46>0,$C45-$C46>0),AND(K46-K45>0,$C46-$C45>0),AND(K45-K46=0,$C45-$C46=0)),2,0)+IF(OR(K45=$C45,K46=$C46),1,0))) -> 0 | ... BJ47: =IF($C45="",0,IF(AND(BJ45=$C45,BJ46=$C46),5,IF(OR(AND(BJ45-BJ46>0,$C45-$C46>0),AND(BJ46-BJ45>0,$C46-$C45>0),AND(BJ45-BJ46=0,$C45-$C46=0)),2,0)+IF(OR(BJ45=$C45,BJ46=$C46),1,0))) -> 0
B48: 0.58333333
A50: 8 | B50: CATAR | D50: 0 | E50: 1 | F50: 0 | G50: 0 | H50: 0 | I50: 0 | J50: 0 | K50: 0 | L50: 0 | M50: 0 | N50: 0 | O50: 0 | P50: 1 | Q50: 1 | R50: 0 | S50: 0 | T50: 0 | U50: 0 | V50: 0 | W50: 0 | X50: 1 | Y50: 0 | Z50: 0 | AA50: 1 | AB50: 0 | AC50: 0 | AD50: 1 | AE50: 0 | AF50: 0 | AG50: 0 | AH50: 0 | AI50: 2 | AJ50: 0 | AK50: 0 | AL50: 2 | AM50: 2 | AN50: 0 | AO50: 0 | AP50: 0 | AQ50: 1 | AR50: 0 | AS50: 0 | AT50: 1 | AU50: 0 | AV50: 1 | AW50: 0 | AX50: 0 | AY50: 0 | AZ50: 0 | BA50: 0 | BB50: 1 | BC50: 0 | BD50: 0 | BE50: 2 | BF50: 0 | BG50: 1 | BH50: 0 | BI50: 0 | BJ50: 0
B51: SUIZA | D51: 2 | E51: 3 | F51: 1 | G51: 2 | H51: 2 | I51: 3 | J51: 2 | K51: 1 | L51: 2 | M51: 3 | N51: 2 | O51: 2 | P51: 2 | Q51: 1 | R51: 2 | S51: 2 | T51: 1 | U51: 3 | V51: 2 | W51: 3 | X51: 2 | Y51: 2 | Z51: 2 | AA51: 2 | AB51: 2 | AC51: 2 | AD51: 3 | AE51: 2 | AF51: 2 | AG51: 2 | AH51: 2 | AI51: 2 | AJ51: 2 | AK51: 2 | AL51: 2 | AM51: 2 | AN51: 3 | AO51: 3 | AP51: 2 | AQ51: 2 | AR51: 3 | AS51: 2 | AT51: 0 | AU51: 2 | AV51: 2 | AW51: 3 | AX51: 2 | AY51: 2 | AZ51: 3 | BA51: 3 | BB51: 1 | BC51: 2 | BD51: 2 | BE51: 1 | BF51: 3 | BG51: 2 | BH51: 2 | BI51: 2 | BJ51: 2
B52: 46186 | C52: PUNTOS | D52: =IF($C50="",0,IF(AND(D50=$C50,D51=$C51),5,IF(OR(AND(D50-D51>0,$C50-$C51>0),AND(D51-D50>0,$C51-$C50>0),AND(D50-D51=0,$C50-$C51=0)),2,0)+IF(OR(D50=$C50,D51=$C51),1,0))) -> 0 | E52: =IF($C50="",0,IF(AND(E50=$C50,E51=$C51),5,IF(OR(AND(E50-E51>0,$C50-$C51>0),AND(E51-E50>0,$C51-$C50>0),AND(E50-E51=0,$C50-$C51=0)),2,0)+IF(OR(E50=$C50,E51=$C51),1,0))) -> 0 | F52: =IF($C50="",0,IF(AND(F50=$C50,F51=$C51),5,IF(OR(AND(F50-F51>0,$C50-$C51>0),AND(F51-F50>0,$C51-$C50>0),AND(F50-F51=0,$C50-$C51=0)),2,0)+IF(OR(F50=$C50,F51=$C51),1,0))) -> 0 | G52: =IF($C50="",0,IF(AND(G50=$C50,G51=$C51),5,IF(OR(AND(G50-G51>0,$C50-$C51>0),AND(G51-G50>0,$C51-$C50>0),AND(G50-G51=0,$C50-$C51=0)),2,0)+IF(OR(G50=$C50,G51=$C51),1,0))) -> 0 | H52: =IF($C50="",0,IF(AND(H50=$C50,H51=$C51),5,IF(OR(AND(H50-H51>0,$C50-$C51>0),AND(H51-H50>0,$C51-$C50>0),AND(H50-H51=0,$C50-$C51=0)),2,0)+IF(OR(H50=$C50,H51=$C51),1,0))) -> 0 | I52: =IF($C50="",0,IF(AND(I50=$C50,I51=$C51),5,IF(OR(AND(I50-I51>0,$C50-$C51>0),AND(I51-I50>0,$C51-$C50>0),AND(I50-I51=0,$C50-$C51=0)),2,0)+IF(OR(I50=$C50,I51=$C51),1,0))) -> 0 | J52: =IF($C50="",0,IF(AND(J50=$C50,J51=$C51),5,IF(OR(AND(J50-J51>0,$C50-$C51>0),AND(J51-J50>0,$C51-$C50>0),AND(J50-J51=0,$C50-$C51=0)),2,0)+IF(OR(J50=$C50,J51=$C51),1,0))) -> 0 | K52: =IF($C50="",0,IF(AND(K50=$C50,K51=$C51),5,IF(OR(AND(K50-K51>0,$C50-$C51>0),AND(K51-K50>0,$C51-$C50>0),AND(K50-K51=0,$C50-$C51=0)),2,0)+IF(OR(K50=$C50,K51=$C51),1,0))) -> 0 | ... BJ52: =IF($C50="",0,IF(AND(BJ50=$C50,BJ51=$C51),5,IF(OR(AND(BJ50-BJ51>0,$C50-$C51>0),AND(BJ51-BJ50>0,$C51-$C50>0),AND(BJ50-BJ51=0,$C50-$C51=0)),2,0)+IF(OR(BJ50=$C50,BJ51=$C51),1,0))) -> 0
B53: 0.58333333
...

Sheet Sumatoria
C5: MARCADOR | D5: ='Polla - Grupos'!C435 -> PUNTOS ACUM | E5: INDICE | G5: RANKING | H5: PUNTOS | I5: Cantidad 5 | J5: Cantidad 3 | K5: Cantidad 2 | L5: Cantidad 1 | M5: DESEMPATE | O5: INDICE DESEMPATE | P5: RANKING DESEMPATE
C6: ='Polla - Grupos'!D8 -> Julian Uribe | D6: ='Polla - Grupos'!D435 -> 0 | E6: =COUNTIF($D$6:$D$64, ">"&D6) + COUNTIF($D$6:D6, D6) -> 1 | G6: =INDEX($C$6:$C$64, MATCH(ROW(A1), $E$6:$E$64, 0)) -> Julian Uribe | H6: =INDEX($D$6:$D$64, MATCH(ROW(A1), $E$6:$E$64, 0)) -> 0 | I6: {=SUMPRODUCT(IFERROR(N(MATCH(ROW('Polla - Grupos'!$D$11:$D$432), {11;16;21;26;31;36;47;52;57;62;67;72;83;88;93;98;103;108;119;124;129;134;139;144;155;160;165;170;175;180;191;196;201;206;211;216;227;232;237;242;247;252;263;268;273;278;283;288;299;304;309;314;319;324;335;340;345;350;355;360;371;376;381;386;391;396;407;412;417;422;427;432}, 0)>0), 0) * (INDEX('Polla - Grupos'!$D$11:$BR$432, 0, MATCH(G6, 'Polla - Grupos'!$D$8:$BR$8, 0))=5))} -> 0 | J6: {=SUMPRODUCT(IFERROR(N(MATCH(ROW('Polla - Grupos'!$D$11:$D$432), {11;16;21;26;31;36;47;52;57;62;67;72;83;88;93;98;103;108;119;124;129;134;139;144;155;160;165;170;175;180;191;196;201;206;211;216;227;232;237;242;247;252;263;268;273;278;283;288;299;304;309;314;319;324;335;340;345;350;355;360;371;376;381;386;391;396;407;412;417;422;427;432}, 0)>0), 0) * (INDEX('Polla - Grupos'!$D$11:$BR$432, 0, MATCH(G6, 'Polla - Grupos'!$D$8:$BR$8, 0))=3))} -> 0 | K6: {=SUMPRODUCT(IFERROR(N(MATCH(ROW('Polla - Grupos'!$D$11:$D$432), {11;16;21;26;31;36;47;52;57;62;67;72;83;88;93;98;103;108;119;124;129;134;139;144;155;160;165;170;175;180;191;196;201;206;211;216;227;232;237;242;247;252;263;268;273;278;283;288;299;304;309;314;319;324;335;340;345;350;355;360;371;376;381;386;391;396;407;412;417;422;427;432}, 0)>0), 0) * (INDEX('Polla - Grupos'!$D$11:$BR$432, 0, MATCH(G6, 'Polla - Grupos'!$D$8:$BR$8, 0))=2))} -> 0 | L6: {=SUMPRODUCT(IFERROR(N(MATCH(ROW('Polla - Grupos'!$D$11:$D$432), {11;16;21;26;31;36;47;52;57;62;67;72;83;88;93;98;103;108;119;124;129;134;139;144;155;160;165;170;175;180;191;196;201;206;211;216;227;232;237;242;247;252;263;268;273;278;283;288;299;304;309;314;319;324;335;340;345;350;355;360;371;376;381;386;391;396;407;412;417;422;427;432}, 0)>0), 0) * (INDEX('Polla - Grupos'!$D$11:$BR$432, 0, MATCH(G6, 'Polla - Grupos'!$D$8:$BR$8, 0))=1))} -> 0 | M6: =H6 + (I6 * 0.001) + (J6 * 0.000001) + (K6 * 0.000000001) + (L6 * 0.000000000001) -> 0 | O6: =COUNTIF($M$6:$M$70, ">"&M6) + COUNTIF($M$6:M6, M6) -> 1 | P6: =INDEX($G$6:$G$70, MATCH(ROW(A1), $O$6:$O$70, 0)) -> Julian Uribe
C7: ='Polla - Grupos'!E8 -> Yulian Sanchez | D7: ='Polla - Grupos'!E435 -> 0 | E7: =COUNTIF($D$6:$D$64, ">"&D7) + COUNTIF($D$6:D7, D7) -> 2 | G7: =INDEX($C$6:$C$64, MATCH(ROW(A2), $E$6:$E$64, 0)) -> Yulian Sanchez | H7: =INDEX($D$6:$D$64, MATCH(ROW(A2), $E$6:$E$64, 0)) -> 0 | I7: {=SUMPRODUCT(IFERROR(N(MATCH(ROW('Polla - Grupos'!$D$11:$D$432), {11;16;21;26;31;36;47;52;57;62;67;72;83;88;93;98;103;108;119;124;129;134;139;144;155;160;165;170;175;180;191;196;201;206;211;216;227;232;237;242;247;252;263;268;273;278;283;288;299;304;309;314;319;324;335;340;345;350;355;360;371;376;381;386;391;396;407;412;417;422;427;432}, 0)>0), 0) * (INDEX('Polla - Grupos'!$D$11:$BR$432, 0, MATCH(G7, 'Polla - Grupos'!$D$8:$BR$8, 0))=5))} -> 0 | J7: {=SUMPRODUCT(IFERROR(N(MATCH(ROW('Polla - Grupos'!$D$11:$D$432), {11;16;21;26;31;36;47;52;57;62;67;72;83;88;93;98;103;108;119;124;129;134;139;144;155;160;165;170;175;180;191;196;201;206;211;216;227;232;237;242;247;252;263;268;273;278;283;288;299;304;309;314;319;324;335;340;345;350;355;360;371;376;381;386;391;396;407;412;417;422;427;432}, 0)>0), 0) * (INDEX('Polla - Grupos'!$D$11:$BR$432, 0, MATCH(G7, 'Polla - Grupos'!$D$8:$BR$8, 0))=3))} -> 0 | K7: {=SUMPRODUCT(IFERROR(N(MATCH(ROW('Polla - Grupos'!$D$11:$D$432), {11;16;21;26;31;36;47;52;57;62;67;72;83;88;93;98;103;108;119;124;129;134;139;144;155;160;165;170;175;180;191;196;201;206;211;216;227;232;237;242;247;252;263;268;273;278;283;288;299;304;309;314;319;324;335;340;345;350;355;360;371;376;381;386;391;396;407;412;417;422;427;432}, 0)>0), 0) * (INDEX('Polla - Grupos'!$D$11:$BR$432, 0, MATCH(G7, 'Polla - Grupos'!$D$8:$BR$8, 0))=2))} -> 0 | L7: {=SUMPRODUCT(IFERROR(N(MATCH(ROW('Polla - Grupos'!$D$11:$D$432), {11;16;21;26;31;36;47;52;57;62;67;72;83;88;93;98;103;108;119;124;129;134;139;144;155;160;165;170;175;180;191;196;201;206;211;216;227;232;237;242;247;252;263;268;273;278;283;288;299;304;309;314;319;324;335;340;345;350;355;360;371;376;381;386;391;396;407;412;417;422;427;432}, 0)>0), 0) * (INDEX('Polla - Grupos'!$D$11:$BR$432, 0, MATCH(G7, 'Polla - Grupos'!$D$8:$BR$8, 0))=1))} -> 0 | M7: =H7 + (I7 * 0.001) + (J7 * 0.000001) + (K7 * 0.000000001) + (L7 * 0.000000000001) -> 0 | O7: =COUNTIF($M$6:$M$70, ">"&M7) + COUNTIF($M$6:M7, M7) -> 2 | P7: =INDEX($G$6:$G$70, MATCH(ROW(A2), $O$6:$O$70, 0)) -> Yulian Sanchez
C8: ='Polla - Grupos'!F8 -> Francisco Moreno | D8: ='Polla - Grupos'!F435 -> 0 | E8: =COUNTIF($D$6:$D$64, ">"&D8) + COUNTIF($D$6:D8, D8) -> 3 | G8: =INDEX($C$6:$C$64, MATCH(ROW(A3), $E$6:$E$64, 0)) -> Francisco Moreno | H8: =INDEX($D$6:$D$64, MATCH(ROW(A3), $E$6:$E$64, 0)) -> 0 | I8: {=SUMPRODUCT(IFERROR(N(MATCH(ROW('Polla - Grupos'!$D$11:$D$432), {11;16;21;26;31;36;47;52;57;62;67;72;83;88;93;98;103;108;119;124;129;134;139;144;155;160;165;170;175;180;191;196;201;206;211;216;227;232;237;242;247;252;263;268;273;278;283;288;299;304;309;314;319;324;335;340;345;350;355;360;371;376;381;386;391;396;407;412;417;422;427;432}, 0)>0), 0) * (INDEX('Polla - Grupos'!$D$11:$BR$432, 0, MATCH(G8, 'Polla - Grupos'!$D$8:$BR$8, 0))=5))} -> 0 | J8: {=SUMPRODUCT(IFERROR(N(MATCH(ROW('Polla - Grupos'!$D$11:$D$432), {11;16;21;26;31;36;47;52;57;62;67;72;83;88;93;98;103;108;119;124;129;134;139;144;155;160;165;170;175;180;191;196;201;206;211;216;227;232;237;242;247;252;263;268;273;278;283;288;299;304;309;314;319;324;335;340;345;350;355;360;371;376;381;386;391;396;407;412;417;422;427;432}, 0)>0), 0) * (INDEX('Polla - Grupos'!$D$11:$BR$432, 0, MATCH(G8, 'Polla - Grupos'!$D$8:$BR$8, 0))=3))} -> 0 | K8: {=SUMPRODUCT(IFERROR(N(MATCH(ROW('Polla - Grupos'!$D$11:$D$432), {11;16;21;26;31;36;47;52;57;62;67;72;83;88;93;98;103;108;119;124;129;134;139;144;155;160;165;170;175;180;191;196;201;206;211;216;227;232;237;242;247;252;263;268;273;278;283;288;299;304;309;314;319;324;335;340;345;350;355;360;371;376;381;386;391;396;407;412;417;422;427;432}, 0)>0), 0) * (INDEX('Polla - Grupos'!$D$11:$BR$432, 0, MATCH(G8, 'Polla - Grupos'!$D$8:$BR$8, 0))=2))} -> 0 | L8: {=SUMPRODUCT(IFERROR(N(MATCH(ROW('Polla - Grupos'!$D$11:$D$432), {11;16;21;26;31;36;47;52;57;62;67;72;83;88;93;98;103;108;119;124;129;134;139;144;155;160;165;170;175;180;191;196;201;206;211;216;227;232;237;242;247;252;263;268;273;278;283;288;299;304;309;314;319;324;335;340;345;350;355;360;371;376;381;386;391;396;407;412;417;422;427;432}, 0)>0), 0) * (INDEX('Polla - Grupos'!$D$11:$BR$432, 0, MATCH(G8, 'Polla - Grupos'!$D$8:$BR$8, 0))=1))} -> 0 | M8: =H8 + (I8 * 0.001) + (J8 * 0.000001) + (K8 * 0.000000001) + (L8 * 0.000000000001) -> 0 | O8: =COUNTIF($M$6:$M$70, ">"&M8) + COUNTIF($M$6:M8, M8) -> 3 | P8: =INDEX($G$6:$G$70, MATCH(ROW(A3), $O$6:$O$70, 0)) -> Francisco Moreno
C9: ='Polla - Grupos'!G8 -> Mauricio Guerrero | D9: ='Polla - Grupos'!G435 -> 0 | E9: =COUNTIF($D$6:$D$64, ">"&D9) + COUNTIF($D$6:D9, D9) -> 4 | G9: =INDEX($C$6:$C$64, MATCH(ROW(A4), $E$6:$E$64, 0)) -> Mauricio Guerrero | H9: =INDEX($D$6:$D$64, MATCH(ROW(A4), $E$6:$E$64, 0)) -> 0 | I9: {=SUMPRODUCT(IFERROR(N(MATCH(ROW('Polla - Grupos'!$D$11:$D$432), {11;16;21;26;31;36;47;52;57;62;67;72;83;88;93;98;103;108;119;124;129;134;139;144;155;160;165;170;175;180;191;196;201;206;211;216;227;232;237;242;247;252;263;268;273;278;283;288;299;304;309;314;319;324;335;340;345;350;355;360;371;376;381;386;391;396;407;412;417;422;427;432}, 0)>0), 0) * (INDEX('Polla - Grupos'!$D$11:$BR$432, 0, MATCH(G9, 'Polla - Grupos'!$D$8:$BR$8, 0))=5))} -> 0 | J9: {=SUMPRODUCT(IFERROR(N(MATCH(ROW('Polla - Grupos'!$D$11:$D$432), {11;16;21;26;31;36;47;52;57;62;67;72;83;88;93;98;103;108;119;124;129;134;139;144;155;160;165;170;175;180;191;196;201;206;211;216;227;232;237;242;247;252;263;268;273;278;283;288;299;304;309;314;319;324;335;340;345;350;355;360;371;376;381;386;391;396;407;412;417;422;427;432}, 0)>0), 0) * (INDEX('Polla - Grupos'!$D$11:$BR$432, 0, MATCH(G9, 'Polla - Grupos'!$D$8:$BR$8, 0))=3))} -> 0 | K9: {=SUMPRODUCT(IFERROR(N(MATCH(ROW('Polla - Grupos'!$D$11:$D$432), {11;16;21;26;31;36;47;52;57;62;67;72;83;88;93;98;103;108;119;124;129;134;139;144;155;160;165;170;175;180;191;196;201;206;211;216;227;232;237;242;247;252;263;268;273;278;283;288;299;304;309;314;319;324;335;340;345;350;355;360;371;376;381;386;391;396;407;412;417;422;427;432}, 0)>0), 0) * (INDEX('Polla - Grupos'!$D$11:$BR$432, 0, MATCH(G9, 'Polla - Grupos'!$D$8:$BR$8, 0))=2))} -> 0 | L9: {=SUMPRODUCT(IFERROR(N(MATCH(ROW('Polla - Grupos'!$D$11:$D$432), {11;16;21;26;31;36;47;52;57;62;67;72;83;88;93;98;103;108;119;124;129;134;139;144;155;160;165;170;175;180;191;196;201;206;211;216;227;232;237;242;247;252;263;268;273;278;283;288;299;304;309;314;319;324;335;340;345;350;355;360;371;376;381;386;391;396;407;412;417;422;427;432}, 0)>0), 0) * (INDEX('Polla - Grupos'!$D$11:$BR$432, 0, MATCH(G9, 'Polla - Grupos'!$D$8:$BR$8, 0))=1))} -> 0 | M9: =H9 + (I9 * 0.001) + (J9 * 0.000001) + (K9 * 0.000000001) + (L9 * 0.000000000001) -> 0 | O9: =COUNTIF($M$6:$M$70, ">"&M9) + COUNTIF($M$6:M9, M9) -> 4 | P9: =INDEX($G$6:$G$70, MATCH(ROW(A4), $O$6:$O$70, 0)) -> Mauricio Guerrero
C10: ='Polla - Grupos'!H8 -> Gustavo Guerrero | D10: ='Polla - Grupos'!H435 -> 0 | E10: =COUNTIF($D$6:$D$64, ">"&D10) + COUNTIF($D$6:D10, D10) -> 5 | G10: =INDEX($C$6:$C$64, MATCH(ROW(A5), $E$6:$E$64, 0)) -> Gustavo Guerrero | H10: =INDEX($D$6:$D$64, MATCH(ROW(A5), $E$6:$E$64, 0)) -> 0 | I10: {=SUMPRODUCT(IFERROR(N(MATCH(ROW('Polla - Grupos'!$D$11:$D$432), {11;16;21;26;31;36;47;52;57;62;67;72;83;88;93;98;103;108;119;124;129;134;139;144;155;160;165;170;175;180;191;196;201;206;211;216;227;232;237;242;247;252;263;268;273;278;283;288;299;304;309;314;319;324;335;340;345;350;355;360;371;376;381;386;391;396;407;412;417;422;427;432}, 0)>0), 0) * (INDEX('Polla - Grupos'!$D$11:$BR$432, 0, MATCH(G10, 'Polla - Grupos'!$D$8:$BR$8, 0))=5))} -> 0 | J10: {=SUMPRODUCT(IFERROR(N(MATCH(ROW('Polla - Grupos'!$D$11:$D$432), {11;16;21;26;31;36;47;52;57;62;67;72;83;88;93;98;103;108;119;124;129;134;139;144;155;160;165;170;175;180;191;196;201;206;211;216;227;232;237;242;247;252;263;268;273;278;283;288;299;304;309;314;319;324;335;340;345;350;355;360;371;376;381;386;391;396;407;412;417;422;427;432}, 0)>0), 0) * (INDEX('Polla - Grupos'!$D$11:$BR$432, 0, MATCH(G10, 'Polla - Grupos'!$D$8:$BR$8, 0))=3))} -> 0 | K10: {=SUMPRODUCT(IFERROR(N(MATCH(ROW('Polla - Grupos'!$D$11:$D$432), {11;16;21;26;31;36;47;52;57;62;67;72;83;88;93;98;103;108;119;124;129;134;139;144;155;160;165;170;175;180;191;196;201;206;211;216;227;232;237;242;247;252;263;268;273;278;283;288;299;304;309;314;319;324;335;340;345;350;355;360;371;376;381;386;391;396;407;412;417;422;427;432}, 0)>0), 0) * (INDEX('Polla - Grupos'!$D$11:$BR$432, 0, MATCH(G10, 'Polla - Grupos'!$D$8:$BR$8, 0))=2))} -> 0 | L10: {=SUMPRODUCT(IFERROR(N(MATCH(ROW('Polla - Grupos'!$D$11:$D$432), {11;16;21;26;31;36;47;52;57;62;67;72;83;88;93;98;103;108;119;124;129;134;139;144;155;160;165;170;175;180;191;196;201;206;211;216;227;232;237;242;247;252;263;268;273;278;283;288;299;304;309;314;319;324;335;340;345;350;355;360;371;376;381;386;391;396;407;412;417;422;427;432}, 0)>0), 0) * (INDEX('Polla - Grupos'!$D$11:$BR$432, 0, MATCH(G10, 'Polla - Grupos'!$D$8:$BR$8, 0))=1))} -> 0 | M10: =H10 + (I10 * 0.001) + (J10 * 0.000001) + (K10 * 0.000000001) + (L10 * 0.000000000001) -> 0 | O10: =COUNTIF($M$6:$M$70, ">"&M10) + COUNTIF($M$6:M10, M10) -> 5 | P10: =INDEX($G$6:$G$70, MATCH(ROW(A5), $O$6:$O$70, 0)) -> Gustavo Guerrero
C11: ='Polla - Grupos'!I8 -> Gerardo Martinez | D11: ='Polla - Grupos'!I435 -> 0 | E11: =COUNTIF($D$6:$D$64, ">"&D11) + COUNTIF($D$6:D11, D11) -> 6 | G11: =INDEX($C$6:$C$64, MATCH(ROW(A6), $E$6:$E$64, 0)) -> Gerardo Martinez | H11: =INDEX($D$6:$D$64, MATCH(ROW(A6), $E$6:$E$64, 0)) -> 0 | I11: {=SUMPRODUCT(IFERROR(N(MATCH(ROW('Polla - Grupos'!$D$11:$D$432), {11;16;21;26;31;36;47;52;57;62;67;72;83;88;93;98;103;108;119;124;129;134;139;144;155;160;165;170;175;180;191;196;201;206;211;216;227;232;237;242;247;252;263;268;273;278;283;288;299;304;309;314;319;324;335;340;345;350;355;360;371;376;381;386;391;396;407;412;417;422;427;432}, 0)>0), 0) * (INDEX('Polla - Grupos'!$D$11:$BR$432, 0, MATCH(G11, 'Polla - Grupos'!$D$8:$BR$8, 0))=5))} -> 0 | J11: {=SUMPRODUCT(IFERROR(N(MATCH(ROW('Polla - Grupos'!$D$11:$D$432), {11;16;21;26;31;36;47;52;57;62;67;72;83;88;93;98;103;108;119;124;129;134;139;144;155;160;165;170;175;180;191;196;201;206;211;216;227;232;237;242;247;252;263;268;273;278;283;288;299;304;309;314;319;324;335;340;345;350;355;360;371;376;381;386;391;396;407;412;417;422;427;432}, 0)>0), 0) * (INDEX('Polla - Grupos'!$D$11:$BR$432, 0, MATCH(G11, 'Polla - Grupos'!$D$8:$BR$8, 0))=3))} -> 0 | K11: {=SUMPRODUCT(IFERROR(N(MATCH(ROW('Polla - Grupos'!$D$11:$D$432), {11;16;21;26;31;36;47;52;57;62;67;72;83;88;93;98;103;108;119;124;129;134;139;144;155;160;165;170;175;180;191;196;201;206;211;216;227;232;237;242;247;252;263;268;273;278;283;288;299;304;309;314;319;324;335;340;345;350;355;360;371;376;381;386;391;396;407;412;417;422;427;432}, 0)>0), 0) * (INDEX('Polla - Grupos'!$D$11:$BR$432, 0, MATCH(G11, 'Polla - Grupos'!$D$8:$BR$8, 0))=2))} -> 0 | L11: {=SUMPRODUCT(IFERROR(N(MATCH(ROW('Polla - Grupos'!$D$11:$D$432), {11;16;21;26;31;36;47;52;57;62;67;72;83;88;93;98;103;108;119;124;129;134;139;144;155;160;165;170;175;180;191;196;201;206;211;216;227;232;237;242;247;252;263;268;273;278;283;288;299;304;309;314;319;324;335;340;345;350;355;360;371;376;381;386;391;396;407;412;417;422;427;432}, 0)>0), 0) * (INDEX('Polla - Grupos'!$D$11:$BR$432, 0, MATCH(G11, 'Polla - Grupos'!$D$8:$BR$8, 0))=1))} -> 0 | M11: =H11 + (I11 * 0.001) + (J11 * 0.000001) + (K11 * 0.000000001) + (L11 * 0.000000000001) -> 0 | O11: =COUNTIF($M$6:$M$70, ">"&M11) + COUNTIF($M$6:M11, M11) -> 6 | P11: =INDEX($G$6:$G$70, MATCH(ROW(A6), $O$6:$O$70, 0)) -> Gerardo Martinez
C12: ='Polla - Grupos'!J8 -> Nora Perez | D12: ='Polla - Grupos'!J435 -> 0 | E12: =COUNTIF($D$6:$D$64, ">"&D12) + COUNTIF($D$6:D12, D12) -> 7 | G12: =INDEX($C$6:$C$64, MATCH(ROW(A7), $E$6:$E$64, 0)) -> Nora Perez | H12: =INDEX($D$6:$D$64, MATCH(ROW(A7), $E$6:$E$64, 0)) -> 0 | I12: {=SUMPRODUCT(IFERROR(N(MATCH(ROW('Polla - Grupos'!$D$11:$D$432), {11;16;21;26;31;36;47;52;57;62;67;72;83;88;93;98;103;108;119;124;129;134;139;144;155;160;165;170;175;180;191;196;201;206;211;216;227;232;237;242;247;252;263;268;273;278;283;288;299;304;309;314;319;324;335;340;345;350;355;360;371;376;381;386;391;396;407;412;417;422;427;432}, 0)>0), 0) * (INDEX('Polla - Grupos'!$D$11:$BR$432, 0, MATCH(G12, 'Polla - Grupos'!$D$8:$BR$8, 0))=5))} -> 0 | J12: {=SUMPRODUCT(IFERROR(N(MATCH(ROW('Polla - Grupos'!$D$11:$D$432), {11;16;21;26;31;36;47;52;57;62;67;72;83;88;93;98;103;108;119;124;129;134;139;144;155;160;165;170;175;180;191;196;201;206;211;216;227;232;237;242;247;252;263;268;273;278;283;288;299;304;309;314;319;324;335;340;345;350;355;360;371;376;381;386;391;396;407;412;417;422;427;432}, 0)>0), 0) * (INDEX('Polla - Grupos'!$D$11:$BR$432, 0, MATCH(G12, 'Polla - Grupos'!$D$8:$BR$8, 0))=3))} -> 0 | K12: {=SUMPRODUCT(IFERROR(N(MATCH(ROW('Polla - Grupos'!$D$11:$D$432), {11;16;21;26;31;36;47;52;57;62;67;72;83;88;93;98;103;108;119;124;129;134;139;144;155;160;165;170;175;180;191;196;201;206;211;216;227;232;237;242;247;252;263;268;273;278;283;288;299;304;309;314;319;324;335;340;345;350;355;360;371;376;381;386;391;396;407;412;417;422;427;432}, 0)>0), 0) * (INDEX('Polla - Grupos'!$D$11:$BR$432, 0, MATCH(G12, 'Polla - Grupos'!$D$8:$BR$8, 0))=2))} -> 0 | L12: {=SUMPRODUCT(IFERROR(N(MATCH(ROW('Polla - Grupos'!$D$11:$D$432), {11;16;21;26;31;36;47;52;57;62;67;72;83;88;93;98;103;108;119;124;129;134;139;144;155;160;165;170;175;180;191;196;201;206;211;216;227;232;237;242;247;252;263;268;273;278;283;288;299;304;309;314;319;324;335;340;345;350;355;360;371;376;381;386;391;396;407;412;417;422;427;432}, 0)>0), 0) * (INDEX('Polla - Grupos'!$D$11:$BR$432, 0, MATCH(G12, 'Polla - Grupos'!$D$8:$BR$8, 0))=1))} -> 0 | M12: =H12 + (I12 * 0.001) + (J12 * 0.000001) + (K12 * 0.000000001) + (L12 * 0.000000000001) -> 0 | O12: =COUNTIF($M$6:$M$70, ">"&M12) + COUNTIF($M$6:M12, M12) -> 7 | P12: =INDEX($G$6:$G$70, MATCH(ROW(A7), $O$6:$O$70, 0)) -> Nora Perez
C13: ='Polla - Grupos'!K8 -> Laura Rodriguez | D13: ='Polla - Grupos'!K435 -> 0 | E13: =COUNTIF($D$6:$D$64, ">"&D13) + COUNTIF($D$6:D13, D13) -> 8 | G13: =INDEX($C$6:$C$64, MATCH(ROW(A8), $E$6:$E$64, 0)) -> Laura Rodriguez | H13: =INDEX($D$6:$D$64, MATCH(ROW(A8), $E$6:$E$64, 0)) -> 0 | I13: {=SUMPRODUCT(IFERROR(N(MATCH(ROW('Polla - Grupos'!$D$11:$D$432), {11;16;21;26;31;36;47;52;57;62;67;72;83;88;93;98;103;108;119;124;129;134;139;144;155;160;165;170;175;180;191;196;201;206;211;216;227;232;237;242;247;252;263;268;273;278;283;288;299;304;309;314;319;324;335;340;345;350;355;360;371;376;381;386;391;396;407;412;417;422;427;432}, 0)>0), 0) * (INDEX('Polla - Grupos'!$D$11:$BR$432, 0, MATCH(G13, 'Polla - Grupos'!$D$8:$BR$8, 0))=5))} -> 0 | J13: {=SUMPRODUCT(IFERROR(N(MATCH(ROW('Polla - Grupos'!$D$11:$D$432), {11;16;21;26;31;36;47;52;57;62;67;72;83;88;93;98;103;108;119;124;129;134;139;144;155;160;165;170;175;180;191;196;201;206;211;216;227;232;237;242;247;252;263;268;273;278;283;288;299;304;309;314;319;324;335;340;345;350;355;360;371;376;381;386;391;396;407;412;417;422;427;432}, 0)>0), 0) * (INDEX('Polla - Grupos'!$D$11:$BR$432, 0, MATCH(G13, 'Polla - Grupos'!$D$8:$BR$8, 0))=3))} -> 0 | K13: {=SUMPRODUCT(IFERROR(N(MATCH(ROW('Polla - Grupos'!$D$11:$D$432), {11;16;21;26;31;36;47;52;57;62;67;72;83;88;93;98;103;108;119;124;129;134;139;144;155;160;165;170;175;180;191;196;201;206;211;216;227;232;237;242;247;252;263;268;273;278;283;288;299;304;309;314;319;324;335;340;345;350;355;360;371;376;381;386;391;396;407;412;417;422;427;432}, 0)>0), 0) * (INDEX('Polla - Grupos'!$D$11:$BR$432, 0, MATCH(G13, 'Polla - Grupos'!$D$8:$BR$8, 0))=2))} -> 0 | L13: {=SUMPRODUCT(IFERROR(N(MATCH(ROW('Polla - Grupos'!$D$11:$D$432), {11;16;21;26;31;36;47;52;57;62;67;72;83;88;93;98;103;108;119;124;129;134;139;144;155;160;165;170;175;180;191;196;201;206;211;216;227;232;237;242;247;252;263;268;273;278;283;288;299;304;309;314;319;324;335;340;345;350;355;360;371;376;381;386;391;396;407;412;417;422;427;432}, 0)>0), 0) * (INDEX('Polla - Grupos'!$D$11:$BR$432, 0, MATCH(G13, 'Polla - Grupos'!$D$8:$BR$8, 0))=1))} -> 0 | M13: =H13 + (I13 * 0.001) + (J13 * 0.000001) + (K13 * 0.000000001) + (L13 * 0.000000000001) -> 0 | O13: =COUNTIF($M$6:$M$70, ">"&M13) + COUNTIF($M$6:M13, M13) -> 8 | P13: =INDEX($G$6:$G$70, MATCH(ROW(A8), $O$6:$O$70, 0)) -> Laura Rodriguez
C14: ='Polla - Grupos'!L8 -> Jhoana Moreno | D14: ='Polla - Grupos'!L435 -> 0 | E14: =COUNTIF($D$6:$D$64, ">"&D14) + COUNTIF($D$6:D14, D14) -> 9 | G14: =INDEX($C$6:$C$64, MATCH(ROW(A9), $E$6:$E$64, 0)) -> Jhoana Moreno | H14: =INDEX($D$6:$D$64, MATCH(ROW(A9), $E$6:$E$64, 0)) -> 0 | I14: {=SUMPRODUCT(IFERROR(N(MATCH(ROW('Polla - Grupos'!$D$11:$D$432), {11;16;21;26;31;36;47;52;57;62;67;72;83;88;93;98;103;108;119;124;129;134;139;144;155;160;165;170;175;180;191;196;201;206;211;216;227;232;237;242;247;252;263;268;273;278;283;288;299;304;309;314;319;324;335;340;345;350;355;360;371;376;381;386;391;396;407;412;417;422;427;432}, 0)>0), 0) * (INDEX('Polla - Grupos'!$D$11:$BR$432, 0, MATCH(G14, 'Polla - Grupos'!$D$8:$BR$8, 0))=5))} -> 0 | J14: {=SUMPRODUCT(IFERROR(N(MATCH(ROW('Polla - Grupos'!$D$11:$D$432), {11;16;21;26;31;36;47;52;57;62;67;72;83;88;93;98;103;108;119;124;129;134;139;144;155;160;165;170;175;180;191;196;201;206;211;216;227;232;237;242;247;252;263;268;273;278;283;288;299;304;309;314;319;324;335;340;345;350;355;360;371;376;381;386;391;396;407;412;417;422;427;432}, 0)>0), 0) * (INDEX('Polla - Grupos'!$D$11:$BR$432, 0, MATCH(G14, 'Polla - Grupos'!$D$8:$BR$8, 0))=3))} -> 0 | K14: {=SUMPRODUCT(IFERROR(N(MATCH(ROW('Polla - Grupos'!$D$11:$D$432), {11;16;21;26;31;36;47;52;57;62;67;72;83;88;93;98;103;108;119;124;129;134;139;144;155;160;165;170;175;180;191;196;201;206;211;216;227;232;237;242;247;252;263;268;273;278;283;288;299;304;309;314;319;324;335;340;345;350;355;360;371;376;381;386;391;396;407;412;417;422;427;432}, 0)>0), 0) * (INDEX('Polla - Grupos'!$D$11:$BR$432, 0, MATCH(G14, 'Polla - Grupos'!$D$8:$BR$8, 0))=2))} -> 0 | L14: {=SUMPRODUCT(IFERROR(N(MATCH(ROW('Polla - Grupos'!$D$11:$D$432), {11;16;21;26;31;36;47;52;57;62;67;72;83;88;93;98;103;108;119;124;129;134;139;144;155;160;165;170;175;180;191;196;201;206;211;216;227;232;237;242;247;252;263;268;273;278;283;288;299;304;309;314;319;324;335;340;345;350;355;360;371;376;381;386;391;396;407;412;417;422;427;432}, 0)>0), 0) * (INDEX('Polla - Grupos'!$D$11:$BR$432, 0, MATCH(G14, 'Polla - Grupos'!$D$8:$BR$8, 0))=1))} -> 0 | M14: =H14 + (I14 * 0.001) + (J14 * 0.000001) + (K14 * 0.000000001) + (L14 * 0.000000000001) -> 0 | O14: =COUNTIF($M$6:$M$70, ">"&M14) + COUNTIF($M$6:M14, M14) -> 9 | P14: =INDEX($G$6:$G$70, MATCH(ROW(A9), $O$6:$O$70, 0)) -> Jhoana Moreno
C15: ='Polla - Grupos'!M8 -> Yoselin Salinas | D15: ='Polla - Grupos'!M435 -> 0 | E15: =COUNTIF($D$6:$D$64, ">"&D15) + COUNTIF($D$6:D15, D15) -> 10 | G15: =INDEX($C$6:$C$64, MATCH(ROW(A10), $E$6:$E$64, 0)) -> Yoselin Salinas | H15: =INDEX($D$6:$D$64, MATCH(ROW(A10), $E$6:$E$64, 0)) -> 0 | I15: {=SUMPRODUCT(IFERROR(N(MATCH(ROW('Polla - Grupos'!$D$11:$D$432), {11;16;21;26;31;36;47;52;57;62;67;72;83;88;93;98;103;108;119;124;129;134;139;144;155;160;165;170;175;180;191;196;201;206;211;216;227;232;237;242;247;252;263;268;273;278;283;288;299;304;309;314;319;324;335;340;345;350;355;360;371;376;381;386;391;396;407;412;417;422;427;432}, 0)>0), 0) * (INDEX('Polla - Grupos'!$D$11:$BR$432, 0, MATCH(G15, 'Polla - Grupos'!$D$8:$BR$8, 0))=5))} -> 0 | J15: {=SUMPRODUCT(IFERROR(N(MATCH(ROW('Polla - Grupos'!$D$11:$D$432), {11;16;21;26;31;36;47;52;57;62;67;72;83;88;93;98;103;108;119;124;129;134;139;144;155;160;165;170;175;180;191;196;201;206;211;216;227;232;237;242;247;252;263;268;273;278;283;288;299;304;309;314;319;324;335;340;345;350;355;360;371;376;381;386;391;396;407;412;417;422;427;432}, 0)>0), 0) * (INDEX('Polla - Grupos'!$D$11:$BR$432, 0, MATCH(G15, 'Polla - Grupos'!$D$8:$BR$8, 0))=3))} -> 0 | K15: {=SUMPRODUCT(IFERROR(N(MATCH(ROW('Polla - Grupos'!$D$11:$D$432), {11;16;21;26;31;36;47;52;57;62;67;72;83;88;93;98;103;108;119;124;129;134;139;144;155;160;165;170;175;180;191;196;201;206;211;216;227;232;237;242;247;252;263;268;273;278;283;288;299;304;309;314;319;324;335;340;345;350;355;360;371;376;381;386;391;396;407;412;417;422;427;432}, 0)>0), 0) * (INDEX('Polla - Grupos'!$D$11:$BR$432, 0, MATCH(G15, 'Polla - Grupos'!$D$8:$BR$8, 0))=2))} -> 0 | L15: {=SUMPRODUCT(IFERROR(N(MATCH(ROW('Polla - Grupos'!$D$11:$D$432), {11;16;21;26;31;36;47;52;57;62;67;72;83;88;93;98;103;108;119;124;129;134;139;144;155;160;165;170;175;180;191;196;201;206;211;216;227;232;237;242;247;252;263;268;273;278;283;288;299;304;309;314;319;324;335;340;345;350;355;360;371;376;381;386;391;396;407;412;417;422;427;432}, 0)>0), 0) * (INDEX('Polla - Grupos'!$D$11:$BR$432, 0, MATCH(G15, 'Polla - Grupos'!$D$8:$BR$8, 0))=1))} -> 0 | M15: =H15 + (I15 * 0.001) + (J15 * 0.000001) + (K15 * 0.000000001) + (L15 * 0.000000000001) -> 0 | O15: =COUNTIF($M$6:$M$70, ">"&M15) + COUNTIF($M$6:M15, M15) -> 10 | P15: =INDEX($G$6:$G$70, MATCH(ROW(A10), $O$6:$O$70, 0)) -> Yoselin Salinas
C16: ='Polla - Grupos'!N8 -> Luis Diaz | D16: ='Polla - Grupos'!N435 -> 0 | E16: =COUNTIF($D$6:$D$64, ">"&D16) + COUNTIF($D$6:D16, D16) -> 11 | G16: =INDEX($C$6:$C$64, MATCH(ROW(A11), $E$6:$E$64, 0)) -> Luis Diaz | H16: =INDEX($D$6:$D$64, MATCH(ROW(A11), $E$6:$E$64, 0)) -> 0 | I16: {=SUMPRODUCT(IFERROR(N(MATCH(ROW('Polla - Grupos'!$D$11:$D$432), {11;16;21;26;31;36;47;52;57;62;67;72;83;88;93;98;103;108;119;124;129;134;139;144;155;160;165;170;175;180;191;196;201;206;211;216;227;232;237;242;247;252;263;268;273;278;283;288;299;304;309;314;319;324;335;340;345;350;355;360;371;376;381;386;391;396;407;412;417;422;427;432}, 0)>0), 0) * (INDEX('Polla - Grupos'!$D$11:$BR$432, 0, MATCH(G16, 'Polla - Grupos'!$D$8:$BR$8, 0))=5))} -> 0 | J16: {=SUMPRODUCT(IFERROR(N(MATCH(ROW('Polla - Grupos'!$D$11:$D$432), {11;16;21;26;31;36;47;52;57;62;67;72;83;88;93;98;103;108;119;124;129;134;139;144;155;160;165;170;175;180;191;196;201;206;211;216;227;232;237;242;247;252;263;268;273;278;283;288;299;304;309;314;319;324;335;340;345;350;355;360;371;376;381;386;391;396;407;412;417;422;427;432}, 0)>0), 0) * (INDEX('Polla - Grupos'!$D$11:$BR$432, 0, MATCH(G16, 'Polla - Grupos'!$D$8:$BR$8, 0))=3))} -> 0 | K16: {=SUMPRODUCT(IFERROR(N(MATCH(ROW('Polla - Grupos'!$D$11:$D$432), {11;16;21;26;31;36;47;52;57;62;67;72;83;88;93;98;103;108;119;124;129;134;139;144;155;160;165;170;175;180;191;196;201;206;211;216;227;232;237;242;247;252;263;268;273;278;283;288;299;304;309;314;319;324;335;340;345;350;355;360;371;376;381;386;391;396;407;412;417;422;427;432}, 0)>0), 0) * (INDEX('Polla - Grupos'!$D$11:$BR$432, 0, MATCH(G16, 'Polla - Grupos'!$D$8:$BR$8, 0))=2))} -> 0 | L16: {=SUMPRODUCT(IFERROR(N(MATCH(ROW('Polla - Grupos'!$D$11:$D$432), {11;16;21;26;31;36;47;52;57;62;67;72;83;88;93;98;103;108;119;124;129;134;139;144;155;160;165;170;175;180;191;196;201;206;211;216;227;232;237;242;247;252;263;268;273;278;283;288;299;304;309;314;319;324;335;340;345;350;355;360;371;376;381;386;391;396;407;412;417;422;427;432}, 0)>0), 0) * (INDEX('Polla - Grupos'!$D$11:$BR$432, 0, MATCH(G16, 'Polla - Grupos'!$D$8:$BR$8, 0))=1))} -> 0 | M16: =H16 + (I16 * 0.001) + (J16 * 0.000001) + (K16 * 0.000000001) + (L16 * 0.000000000001) -> 0 | O16: =COUNTIF($M$6:$M$70, ">"&M16) + COUNTIF($M$6:M16, M16) -> 11 | P16: =INDEX($G$6:$G$70, MATCH(ROW(A11), $O$6:$O$70, 0)) -> Luis Diaz
C17: ='Polla - Grupos'!O8 -> Diela del Carmen | D17: ='Polla - Grupos'!O435 -> 0 | E17: =COUNTIF($D$6:$D$64, ">"&D17) + COUNTIF($D$6:D17, D17) -> 12 | G17: =INDEX($C$6:$C$64, MATCH(ROW(A12), $E$6:$E$64, 0)) -> Diela del Carmen | H17: =INDEX($D$6:$D$64, MATCH(ROW(A12), $E$6:$E$64, 0)) -> 0 | I17: {=SUMPRODUCT(IFERROR(N(MATCH(ROW('Polla - Grupos'!$D$11:$D$432), {11;16;21;26;31;36;47;52;57;62;67;72;83;88;93;98;103;108;119;124;129;134;139;144;155;160;165;170;175;180;191;196;201;206;211;216;227;232;237;242;247;252;263;268;273;278;283;288;299;304;309;314;319;324;335;340;345;350;355;360;371;376;381;386;391;396;407;412;417;422;427;432}, 0)>0), 0) * (INDEX('Polla - Grupos'!$D$11:$BR$432, 0, MATCH(G17, 'Polla - Grupos'!$D$8:$BR$8, 0))=5))} -> 0 | J17: {=SUMPRODUCT(IFERROR(N(MATCH(ROW('Polla - Grupos'!$D$11:$D$432), {11;16;21;26;31;36;47;52;57;62;67;72;83;88;93;98;103;108;119;124;129;134;139;144;155;160;165;170;175;180;191;196;201;206;211;216;227;232;237;242;247;252;263;268;273;278;283;288;299;304;309;314;319;324;335;340;345;350;355;360;371;376;381;386;391;396;407;412;417;422;427;432}, 0)>0), 0) * (INDEX('Polla - Grupos'!$D$11:$BR$432, 0, MATCH(G17, 'Polla - Grupos'!$D$8:$BR$8, 0))=3))} -> 0 | K17: {=SUMPRODUCT(IFERROR(N(MATCH(ROW('Polla - Grupos'!$D$11:$D$432), {11;16;21;26;31;36;47;52;57;62;67;72;83;88;93;98;103;108;119;124;129;134;139;144;155;160;165;170;175;180;191;196;201;206;211;216;227;232;237;242;247;252;263;268;273;278;283;288;299;304;309;314;319;324;335;340;345;350;355;360;371;376;381;386;391;396;407;412;417;422;427;432}, 0)>0), 0) * (INDEX('Polla - Grupos'!$D$11:$BR$432, 0, MATCH(G17, 'Polla - Grupos'!$D$8:$BR$8, 0))=2))} -> 0 | L17: {=SUMPRODUCT(IFERROR(N(MATCH(ROW('Polla - Grupos'!$D$11:$D$432), {11;16;21;26;31;36;47;52;57;62;67;72;83;88;93;98;103;108;119;124;129;134;139;144;155;160;165;170;175;180;191;196;201;206;211;216;227;232;237;242;247;252;263;268;273;278;283;288;299;304;309;314;319;324;335;340;345;350;355;360;371;376;381;386;391;396;407;412;417;422;427;432}, 0)>0), 0) * (INDEX('Polla - Grupos'!$D$11:$BR$432, 0, MATCH(G17, 'Polla - Grupos'!$D$8:$BR$8, 0))=1))} -> 0 | M17: =H17 + (I17 * 0.001) + (J17 * 0.000001) + (K17 * 0.000000001) + (L17 * 0.000000000001) -> 0 | O17: =COUNTIF($M$6:$M$70, ">"&M17) + COUNTIF($M$6:M17, M17) -> 12 | P17: =INDEX($G$6:$G$70, MATCH(ROW(A12), $O$6:$O$70, 0)) -> Diela del Carmen
C18: ='Polla - Grupos'!P8 -> Paola Agredo | D18: ='Polla - Grupos'!P435 -> 0 | E18: =COUNTIF($D$6:$D$64, ">"&D18) + COUNTIF($D$6:D18, D18) -> 13 | G18: =INDEX($C$6:$C$64, MATCH(ROW(A13), $E$6:$E$64, 0)) -> Paola Agredo | H18: =INDEX($D$6:$D$64, MATCH(ROW(A13), $E$6:$E$64, 0)) -> 0 | I18: {=SUMPRODUCT(IFERROR(N(MATCH(ROW('Polla - Grupos'!$D$11:$D$432), {11;16;21;26;31;36;47;52;57;62;67;72;83;88;93;98;103;108;119;124;129;134;139;144;155;160;165;170;175;180;191;196;201;206;211;216;227;232;237;242;247;252;263;268;273;278;283;288;299;304;309;314;319;324;335;340;345;350;355;360;371;376;381;386;391;396;407;412;417;422;427;432}, 0)>0), 0) * (INDEX('Polla - Grupos'!$D$11:$BR$432, 0, MATCH(G18, 'Polla - Grupos'!$D$8:$BR$8, 0))=5))} -> 0 | J18: {=SUMPRODUCT(IFERROR(N(MATCH(ROW('Polla - Grupos'!$D$11:$D$432), {11;16;21;26;31;36;47;52;57;62;67;72;83;88;93;98;103;108;119;124;129;134;139;144;155;160;165;170;175;180;191;196;201;206;211;216;227;232;237;242;247;252;263;268;273;278;283;288;299;304;309;314;319;324;335;340;345;350;355;360;371;376;381;386;391;396;407;412;417;422;427;432}, 0)>0), 0) * (INDEX('Polla - Grupos'!$D$11:$BR$432, 0, MATCH(G18, 'Polla - Grupos'!$D$8:$BR$8, 0))=3))} -> 0 | K18: {=SUMPRODUCT(IFERROR(N(MATCH(ROW('Polla - Grupos'!$D$11:$D$432), {11;16;21;26;31;36;47;52;57;62;67;72;83;88;93;98;103;108;119;124;129;134;139;144;155;160;165;170;175;180;191;196;201;206;211;216;227;232;237;242;247;252;263;268;273;278;283;288;299;304;309;314;319;324;335;340;345;350;355;360;371;376;381;386;391;396;407;412;417;422;427;432}, 0)>0), 0) * (INDEX('Polla - Grupos'!$D$11:$BR$432, 0, MATCH(G18, 'Polla - Grupos'!$D$8:$BR$8, 0))=2))} -> 0 | L18: {=SUMPRODUCT(IFERROR(N(MATCH(ROW('Polla - Grupos'!$D$11:$D$432), {11;16;21;26;31;36;47;52;57;62;67;72;83;88;93;98;103;108;119;124;129;134;139;144;155;160;165;170;175;180;191;196;201;206;211;216;227;232;237;242;247;252;263;268;273;278;283;288;299;304;309;314;319;324;335;340;345;350;355;360;371;376;381;386;391;396;407;412;417;422;427;432}, 0)>0), 0) * (INDEX('Polla - Grupos'!$D$11:$BR$432, 0, MATCH(G18, 'Polla - Grupos'!$D$8:$BR$8, 0))=1))} -> 0 | M18: =H18 + (I18 * 0.001) + (J18 * 0.000001) + (K18 * 0.000000001) + (L18 * 0.000000000001) -> 0 | O18: =COUNTIF($M$6:$M$70, ">"&M18) + COUNTIF($M$6:M18, M18) -> 13 | P18: =INDEX($G$6:$G$70, MATCH(ROW(A13), $O$6:$O$70, 0)) -> Paola Agredo
